20221223 13:02:26 INFO     engine : served at port: "8000".
20221223 13:02:26 INFO     engine : platform: "Linux-5.10.63-v7l+-armv7l-with-debian-10.11".
20221223 13:02:26 INFO     engine : machine: "armv7l".
20221223 13:02:26 INFO     engine : python version: "3.7.3".
20221223 13:02:26 INFO     engine : django version: "(3, 2, 16, 'final', 0)".
20221223 13:02:26 INFO     engine : bots version: "3.3.0".
20221223 13:02:26 INFO     engine : bots installation path: "/home/pi/Documents/raspimapper/bots/utils".
20221223 13:02:26 INFO     engine : config path: "/home/pi/Documents/raspimapper/raspimapper".
20221223 13:02:26 INFO     engine : botssys path: "/home/pi/Documents/raspimapper/bots/utils/botssys".
20221223 13:02:26 INFO     engine : usersys path: "/home/pi/Documents/raspimapper/bots/usersys".
20221223 13:02:26 INFO     engine : local date/time: "2022-12-23T13:02:26.289782".
20221223 13:02:26 INFO     engine : DATABASE_ENGINE: "django.db.backends.sqlite3".
20221223 13:02:26 INFO     engine : DATABASE_NAME: "/home/pi/Documents/raspimapper/db.sqlite3".
20221223 13:02:26 INFO     engine : DATABASE_USER: "".
20221223 13:02:26 INFO     engine : DATABASE_HOST: "".
20221223 13:02:26 INFO     engine : DATABASE_PORT: "".
20221223 13:02:26 INFO     engine : DATABASE_OPTIONS: "{}".
20221223 13:02:26 INFO     engine : Connected to database.
20221223 13:02:26 DEBUG    engine : No import of module "/home/pi/Documents/raspimapper/bots/usersys/routescripts/botsengine": No module named 'bots.usersys.routescripts.botsengine'.
20221223 13:02:26 INFO     engine : This run is an acceptance test - as indicated in option "runacceptancetest" in bots.ini.
20221223 13:02:26 DEBUG    engine : Imported "/home/pi/Documents/raspimapper/bots/usersys/routescripts/bots_acceptancetest".
20221223 13:02:26 CRITICAL engine : !Bots database is locked!
Bots-engine has ended in an unexpected way during the last run.
Most likely causes: sudden power-down, system crash, problems with disk I/O, bots-engine terminated by user, etc.
Bots will do an automatic crash recovery now.
20221223 13:02:26 DEBUG    engine : Run userscript "pretest" in "/home/pi/Documents/raspimapper/bots/usersys/routescripts/bots_acceptancetest".
20221223 13:02:26 INFO     engine : Run "crashrecovery".
20221223 13:02:26 INFO     engine : Run all active routes from database: "['myfirstroute']".
20221223 13:02:26 DEBUG    engine : No import of module "/home/pi/Documents/raspimapper/bots/usersys/routescripts/myfirstroute": No module named 'bots.usersys.routescripts.myfirstroute'.
20221223 13:02:26 INFO     engine : Running route myfirstroute 9999
20221223 13:02:26 DEBUG    engine : Start communication channel "myfirstroute_in" type file in.
20221223 13:02:26 DEBUG    engine : Channel "myfirstroute_in" adapted for acceptance test: type "file", testpath "".
20221223 13:02:26 DEBUG    engine : No import of module "/home/pi/Documents/raspimapper/bots/usersys/communicationscripts/myfirstroute_in": No module named 'bots.usersys.communicationscripts.myfirstroute_in'.
20221223 13:02:26 DEBUG    engine : Finished communication channel "myfirstroute_in" type file in.
20221223 13:02:32 DEBUG    engine : Error in process: Traceback (most recent call last):
  File "/home/pi/Documents/raspimapper/bots/utils/botslib.py", line 448, in wrapper
    terug = func(*args,**argv)
  File "/home/pi/Documents/raspimapper/bots/utils/engine/router.py", line 151, in routepart
    nr_of_incoming_files_for_channel = botslib.updateinfo(change=change,where=where)
  File "/home/pi/Documents/raspimapper/bots/utils/botslib.py", line 306, in updateinfo
    return updateinfocore(change=change,where=where,wherestring=wherestring, wheredict=wheredict)
  File "/home/pi/Documents/raspimapper/bots/utils/botslib.py", line 292, in updateinfocore
    idta = queryset.pk
AttributeError: 'QuerySet' object has no attribute 'pk'

20221223 13:02:32 DEBUG    engine : Finished route myfirstroute 9999
20221223 13:02:32 ERROR    engine : Error in automatic maintenance.
Traceback (most recent call last):
  File "/home/pi/Documents/raspimapper/bots/utils/engine/router.py", line 242, in evaluate
    return automaticmaintenance.evaluate(self.command,self.get_minta4query())
  File "/home/pi/Documents/raspimapper/bots/utils/engine/automaticmaintenance.py", line 29, in evaluate
    make_run_report(rootidtaofrun,resultsofrun,command,totalfilesize)
  File "/home/pi/Documents/raspimapper/bots/utils/engine/automaticmaintenance.py", line 51, in make_run_report
    rootta.synall()    #to get the timestamp of this run
  File "/home/pi/Documents/raspimapper/bots/utils/botslib.py", line 105, in synall
    self.__dict__.update(queryset)
TypeError: 'Transaction' object is not iterable
20221223 13:02:33 INFO     engine : Run "new".
20221223 13:02:33 INFO     engine : Run active routes from database that are in default run: "['myfirstroute']".
20221223 13:02:33 DEBUG    engine : No import of module "/home/pi/Documents/raspimapper/bots/usersys/routescripts/myfirstroute".
20221223 13:02:33 INFO     engine : Running route myfirstroute 9999
20221223 13:02:33 DEBUG    engine : Start communication channel "myfirstroute_in" type file in.
20221223 13:02:33 DEBUG    engine : Channel "myfirstroute_in" adapted for acceptance test: type "file", testpath "".
20221223 13:02:33 DEBUG    engine : No import of module "/home/pi/Documents/raspimapper/bots/usersys/communicationscripts/myfirstroute_in".
20221223 13:02:34 DEBUG    engine : Finished communication channel "myfirstroute_in" type file in.
